Workbook

Sheet Investicija
B2: Investicijska studija pokretanja društva s ograničenom odgovornošću "KBD špedicija"
B7: Studiju izrađuju: Zdravko Blažević - osnivač i član društva Antonio Dumić - osnivač i član društva Matko Kekez - osnivač i član društva
B13: 1. TROŠKOVI NABAVE KAMIONA I PRIKOLICA
B15: Naziv troška | C15: Jedinična cijena | D15: Količina | E15: Mjerna jedinica | F15: Ukupan iznos
B16: Kamion tegljač Mercedes Benz Actros 2548 LS | C16: 123000 | D16: 10 | E16: kom | F16: =C16*D16 -> 1230000
B17: Otprema kamiona (Njemačka, München) | C17: 30000 | D17: 1 | E17: / | F17: =C17*D17 -> 30000
B18: Registracija i tehnički pregled kamiona | C18: 500 | D18: 10 | E18: kom | F18: =C18*D18 -> 5000
B19: Kasko osiguranje vozila | C19: 3500 | D19: 10 | E19: kom | F19: =C19*D19 -> 35000
B20: Prikolice Schwarzmüller S1 poluprikolica s pomičnim podom | C20: 76000 | D20: 7 | E20: kom | F20: =C20*D20 -> 532000
B21: Prikolice Schmitz Cargobull Reefer Standard Double deck sa hladnjačom | C21: 65000 | D21: 6 | E21: kom | F21: =C21*D21 -> 390000
B22: Registracija i tehnički pregled prikolica | C22: 500 | D22: 13 | E22: kom | F22: =C22*D22 -> 6500
B23: UKUPNO | F23: =SUM(F16:F22) -> 2228500
B26: 2. TROŠKOVI IZGRADNJE INFRASTRUKTURE (ZEMLJIŠTE, HANGAR I UREDI) | I26: 2A. TROŠKOVI PRIKLJUČKA ZA STRUJU
B28: Naziv troška | C28: Jedinična cijena | D28: Količina | E28: Mjerna jedinica | F28: Ukupan iznos | I28: Naziv troška | J28: Jedinična cijena | K28: Količina | L28: Mjerna jedinica | M28: Ukupan iznos
B29: Kupnja zemljišta za izgradnju hangara i ureda - Virovitica, poduzetnička zona "Sjever" | C29: 10 | D29: 3000 | E29: m2 | F29: =C29*D29 -> 30000 | I29: Rasvjeta za cestu i prilaz | J29: 179.18 | K29: 6 | L29: Kw | M29: =J29*K29 -> 1075.08
B30: Priključak plina | C30: 521.82 | D30: 1 | E30: / | F30: =C30*D30 -> 521.82 | I30: Električna energija za urede, wc i kupaonu | J30: 179.18 | K30: 3 | L30: Kw | M30: =J30*K30 -> 537.54
B31: Priključak vode | C31: 135.46 | D31: 1 | E31: / | F31: =C31*D31 -> 135.46 | I31: Električna energija za potrebe hangara | J31: 179.18 | K31: 5 | L31: Kw | M31: =J31*K31 -> 895.9
B32: Priključak kanalizacije | C32: 521.82 | D32: 1 | E32: / | F32: =C32*D32 -> 521.82 | I32: UKUPNO | M32: =SUM(M29:M31) -> 2508.52
B33: Priključak struja (TABLICA 2A) | F33: =M32 -> 2508.52
B34: Izgradnja hangara i ureda (TABLICA 2B) | C34: =J47 -> 0 | F34: =M47 -> 903336.39
B35: UKUPNO | F35: =SUM(F29:F34) -> 937024.01 | I35: 2B. TROŠKOVI HANGARA I UREDA
I37: Naziv troška | J37: Jedinična cijena | K37: Količina | L37: Mjerna jedinica | M37: Ukupan iznos
B38: 3. TROŠKOVI OPREMANJA INFRASTRUKTURE (NAMJEŠTAJ, UREDSKA I INFORMATIČKA OPREMA) | I38: Građevinska dozvola i popratna dokumentacija | J38: 20000 | K38: 1 | L38: / | M38: =J38*K38 -> 20000
I39: Projektiranje objekta (građevinski nacrti, planiranje materijala, broja radnika...) | J39: 20000 | K39: 1 | L39: / | M39: =J39*K39 -> 20000
B40: Naziv troška | C40: Jedinična cijena | D40: Količina | E40: Mjerna jedinica | F40: Ukupan iznos | I40: Stup rasvjetni cijevni konusni ORS-CK1-5m (bez tem.vijaka) | J40: 263.09 | K40: 16 | L40: kom | M40: =J40*K40 -> 4209.44
B41: Automehaničarski set (ključevi, akumulatorski alat, dizalice) | C41: 2500 | D41: 1 | E41: kom | F41: =C41*D41 -> 2500 | I41: Izgradnja hangara za 10 kamiona i 13 prikolica | J41: 700 | K41: 1000 | L41: m2 | M41: =J41*K41 -> 700000
B42: Uređaj za izmjenu guma ms 530 s Beissbarth | C42: 4300 | D42: 1 | E42: kom | F42: =C42*D42 -> 4300 | I42: Asfaltiranje prilaza | J42: 20 | K42: 600 | L42: m2 | M42: =J42*K42 -> 12000
B43: Radijator pločasti bočni Compact 22K, 600x 500 mm, 1052W | C43: 70 | D43: 7 | E43: kom | F43: =C43*D43 -> 490 | I43: Podloga za prilaz (tucanik) | J43: 30 | K43: 200 | L43: m3 | M43: =J43*K43 -> 6000
B44: Brilla wc školjka viseća s kabinom | C44: 150 | D44: 2 | E44: kom | F44: =C44*D44 -> 300 | I44: Betonska ploča | J44: 35 | K44: 72 | L44: m3 | M44: =J44*K44 -> 2520
B45: Pisoar Concepto Presi | C45: 50 | D45: 3 | E45: kom | F45: =C45*D45 -> 150 | I45: Armaturna mreža | J45: 72.32 | K45: 40 | L45: kom | M45: =J45*K45 -> 2892.8
B46: Corniche Kutna tuš kabina Light | C46: 239 | D46: 1 | E46: kom | F46: =C46*D46 -> 239 | I46: Izgradnja 3 ureda s wc-om i čajnom kuhinjom (u cijenu uključeno postavljanje podova, keramike, električne, plinovodne i vodovodne instalacije, žbuka, farbanje, unutarnja rasvjeta i svi popratni troškovi instalacije namještaja i infrastrukture) | J46: 1428.57 | K46: 95 | L46: m2 | M46: =J46*K46 -> 135714.15
B47: Kupaonski namještaj Sarasota 108 (Bodega) | C47: 400 | D47: 1 | E47: set | F47: =C47*D47 -> 400 | I47: UKUPNO | M47: =SUM(M38:M46) -> 903336.39
B48: Respekta Kuhinjski komplet Cuisine (kuhinjski uređaji uključeni) | C48: 1600 | D48: 1 | E48: set | F48: =C48*D48 -> 1600
B49: Namještaj (uredski namještaj "optimal" Svijet namještaja) | C49: 2200 | D49: 3 | E49: set | F49: =C49*D49 -> 6600
B50: Multifunkcijski Fotokopirni uređaj iR2224iF sa DADF | C50: 1499.82 | D50: 1 | E50: kom | F50: =C50*D50 -> 1499.82
B51: UKUPNO | F51: =SUM(F41:F50) -> 18078.82
B54: 4. TROŠKOVI RAČUNALNE OPREME
B56: Naziv troška | C56: Jedinična cijena | D56: Količina | E56: Mjerna jedinica | F56: Ukupan iznos
B57: Stolno računalo HGPC Office Prime 1218S5ND, Intel Core i3 12100, 8 GB, Intel UHD 730, SSD 500 GB NVMe, FreeDOS | C57: 400.35 | D57: 5 | E57: kom | F57: =C57*D57 -> 2001.75
B58: Usmjerivač Cudy WR1200, AC1200, Dual band 2.4GHz/5GHz, 1×WAN, 4×LAN | C58: 39.99 | D58: 1 | E58: kom | F58: =C58*D58 -> 39.99
...

Sheet In + Am
B2: STRUKTURA ULAGANJA
B4: Opis | D4: Iznos | E4: Vlastita sredstva | F4: Kredit | G4: Udio sredstva u ukupnoj investiciji
B5: A. Ulaganje u osnovna sredstva
B6: 1 | C6: Nabava kamiona i prikolice | D6: =Investicija!F23 -> 2228500 | E6: =D6-F6 -> 2228500 | G6: =D6/$D$12 -> 0.69929034
B7: 2 | C7: Izgradnja infrastrukture | D7: =Investicija!F35 -> 937024.01 | E7: =D7-F7 -> 437024.01 | F7: 500000 | G7: =D7/$D$12 -> 0.29403268
B8: 3 | C8: Oprema infrastrukture (namještaj, sanitarije) | D8: =Investicija!F51 -> 18078.82 | E8: =D8-F8 -> 18078.82 | G8: =D8/$D$12 -> 0.0056730286
B9: 4 | C9: Informatička oprema | D9: =Investicija!F61 -> 2659.54 | E9: =D9-F9 -> 2659.54 | G9: =D9/$D$12 -> 0.00083454818
B10: 5 | C10: Troškovi osnivanja | D10: =Investicija!F73 -> 539.84 | E10: =D10-F10 -> 539.84 | G10: =D10/$D$12 -> 0.00016939865
B11: B. Ulaganje u trajna obrtna sredstva | D11: 0 | E11: =D11-F11 -> 0
B12: C. Ukupni iznos ulaganja | D12: =SUM(D5:D11) -> 3186802.2 | E12: =SUM(E5:E11) -> 2686802.2 | F12: =SUM(F5:F11) -> 500000 | G12: =D12/$D$12 -> 1
B13: Odnos vlastitog i tuđeg financiranja | D13: =SUM(E13:F13) -> 1 | E13: =E12/D12 -> 0.84310291 | F13: =F12/D12 -> 0.15689709
B16: OBRAČUN AMORTIZACIJE
B18: Opis | D18: Iznos | E18: % | F18: Amortizacija
B19: A. Ulaganje u osnovna sredstva
B20: 1 | C20: Transportna imovina (tegljači, kamioni, hladnjače i priključna transportna sredstva) | D20: =D6 -> 2228500 | E20: 0.25 | F20: =D20*E20 -> 557125
B21: 2 | C21: Nekretnine (hangar, uredi, prilaz, zemljište, rasvjetni stupovi ) | D21: =D7 -> 937024.01 | E21: 0.05 | F21: =D21*E21 -> 46851.201
B22: 3 | C22: Računala i računalni programi | D22: =D9 -> 2659.54 | E22: 0.5 | F22: =D22*E22 -> 1329.77
B23: 4 | C23: Oprema, alat, invertar, namještaj | D23: =D8 -> 18078.82 | E23: 0.25 | F23: =D23*E23 -> 4519.705
B24: 5 | C24: Nematerijalna imovina (osnivački troškovi) | D24: =D10 -> 539.84 | E24: 0.25 | F24: =D24*E24 -> 134.96
B25: UKUPAN IZNOS AMORTIZACIJE | D25: =SUM(D20:D24) -> 3186802.2 | F25: =SUM(F20:F24) -> 609960.64
B28: OBRAČUN OVP
B30: Br. | C30: Naziv | D30: Nabavna vrijednost | E30: Stopa otpisa | F30: Godina | P30: Ispravljena vrijednost | Q30: Ostatak vrijednosti
F31: 2025 | G31: 2026 | H31: 2027 | I31: 2028 | J31: 2029 | K31: 2030 | L31: 2031 | M31: 2032 | N31: 2033 | O31: 2034
B32: A | C32: Investicija
B33: Transportna imovina (tegljači, kamioni, hladnjače i priključna transportna sredstva) | D33: =D20 -> 2228500 | E33: =E20 -> 0.25 | F33: =D33*E33 -> 557125 | G33: =F33 -> 557125 | H33: =G33 -> 557125 | I33: =H33 -> 557125 | J33: 0 | K33: =J33 -> 0 | L33: =K33 -> 0 | M33: =L33 -> 0 | N33: =M33 -> 0 | O33: =N33 -> 0 | P33: =SUM(F33:O33) -> 2228500 | Q33: =D33-P33 -> 0
B34: Nekretnine (hangar, uredi, prilaz, zemljište, rasvjetni stupovi ) | D34: =D21 -> 937024.01 | E34: =E21 -> 0.05 | F34: =$D$34*$E$34 -> 46851.201 | G34: =$D$34*$E$34 -> 46851.201 | H34: =$D$34*$E$34 -> 46851.201 | I34: =$D$34*$E$34 -> 46851.201 | J34: =$D$34*$E$34 -> 46851.201 | K34: =$D$34*$E$34 -> 46851.201 | L34: =$D$34*$E$34 -> 46851.201 | M34: =$D$34*$E$34 -> 46851.201 | ... O34: =$D$34*$E$34 -> 46851.201 | P34: =SUM(F34:O34) -> 468512.01 | Q34: =D34-P34 -> 468512
B35: Računala i računalni programi | D35: =D22 -> 2659.54 | E35: =E22 -> 0.5 | F35: =$D$35*$E$35 -> 1329.77 | G35: =$D$35*$E$35 -> 1329.77 | H35: 0 | I35: 0 | J35: 0 | K35: 0 | L35: 0 | M35: 0 | N35: 0 | O35: 0 | P35: =SUM(F35:O35) -> 2659.54 | Q35: =D35-P35 -> 0
B36: Oprema, alat, invertar, namještaj | D36: =D23 -> 18078.82 | E36: =E23 -> 0.25 | F36: =$D$36*$E$36 -> 4519.705 | G36: =$D$36*$E$36 -> 4519.705 | H36: =$D$36*$E$36 -> 4519.705 | I36: =$D$36*$E$36 -> 4519.705 | J36: 0 | K36: 0 | L36: 0 | M36: 0 | N36: 0 | O36: 0 | P36: =SUM(F36:O36) -> 18078.82 | Q36: =D36-P36 -> 0
B37: Nematerijalna imovina (osnivački troškovi) | D37: =D24 -> 539.84 | E37: =E24 -> 0.25 | F37: =$D$37*$E$37 -> 134.96 | G37: =$D$37*$E$37 -> 134.96 | H37: =$D$37*$E$37 -> 134.96 | I37: =$D$37*$E$37 -> 134.96 | J37: 0 | K37: 0 | L37: 0 | M37: 0 | N37: 0 | O37: 0 | P37: =SUM(F37:O37) -> 539.84 | Q37: =D37-P37 -> 0
B38: B Sveukupno | D38: =SUM(D33:D37) -> 3186802.2 | E38: =E25 -> 0 | F38: =SUM(F32:F37) -> 609960.64 | G38: =SUM(G32:G37) -> 609960.64 | H38: =SUM(H32:H37) -> 608630.87 | I38: =SUM(I32:I37) -> 608630.87 | J38: =SUM(J32:J37) -> 46851.201 | K38: =SUM(K32:K37) -> 46851.201 | L38: =SUM(L32:L37) -> 46851.201 | M38: =SUM(M32:M37) -> 46851.201 | ... O38: =SUM(O32:O37) -> 46851.201 | P38: =SUM(P33:P37) -> 2718290.2 | Q38: =D38-P38 -> 468512
B39: C Ostatak vrijednosti projekta | D39: =D27 -> 0
B40: 1 Osnovna sredstva | D40: =D38 -> 3186802.2 | F40: =D40-F38 -> 2576841.6 | G40: =F40-G38 -> 1966880.9 | H40: =G40-H38 -> 1358250.1 | I40: =H40-I38 -> 749619.21 | J40: =I40-J38 -> 702768.01 | K40: =J40-K38 -> 655916.81 | L40: =K40-L38 -> 609065.61 | M40: =L40-M38 -> 562214.41 | N40: =M40-N38 -> 515363.21 | O40: =N40-O38 -> 468512 | Q40: =O40 -> 468512
B41: 2 TOBS | D41: =D11 -> 0 | F41: =TOBS!E29 -> -23510.723 | G41: =TOBS!F29 -> -23377.182 | H41: =TOBS!G29 -> -14489.104 | I41: =TOBS!H29 -> -5941.3379 | J41: =TOBS!I29 -> 6643.3246 | K41: =TOBS!J29 -> -1261.0629 | L41: =TOBS!K29 -> -1116.1315 | M41: =TOBS!L29 -> -965.67082 | ... O41: =TOBS!N29 -> -647.30963 | Q41: =O41 -> -647.30963
B42: UKUPNO | D42: =SUM(D40:D41) -> 3186802.2 | F42: =SUM(F40:F41) -> 2553330.9 | G42: =SUM(G40:G41) -> 1943503.8 | H42: =SUM(H40:H41) -> 1343761 | I42: =SUM(I40:I41) -> 743677.87 | J42: =SUM(J40:J41) -> 709411.33 | K42: =SUM(K40:K41) -> 654655.74 | L42: =SUM(L40:L41) -> 607949.47 | M42: =SUM(M40:M41) -> 561248.74 | ... O42: =SUM(O40:O41) -> 467864.7 | Q42: =SUM(Q40:Q41) -> 467864.7

Sheet Prihodi
B2: PRIHODI KROZ GODINE RADA PROJEKTA
B4: GODINA | C4: 2025 | D4: 2026 | E4: 2027 | F4: 2028 | G4: 2029 | H4: 2030 | I4: 2031 | J4: 2032 | K4: 2033 | L4: 2034
B5: UKUPNI PRIHODI | C5: =G14 -> 1226880 | D5: =G20 -> 1226880 | E5: =G26 -> 1524096 | F5: =G32 -> 1814400 | G5: =G38 -> 2410560 | H5: =$G$44 -> 2712960 | I5: =$G$44 -> 2712960 | J5: =$G$44 -> 2712960 | K5: =$G$44 -> 2712960 | L5: =$G$44 -> 2712960
B7: Broj dana u mjesecu | C7: 30
B8: Mjeseci u godini | C8: 12
B11: 2025. GODINA | I11: Kalkulacija prihoda transporta robe unutar granica RH 2025.
B13: Usluga | C13: Jedinica mjere | D13: Jedinična cijena | E13: Količina | F13: Ukupni mjesečni prihod | G13: Ukupni godišnji prihod | I13: Procjenjen broj produktivnih kamiona dnevno (na temelju pretpostavke o potražnji za našim uslugama) | J13: Prosječna brzina kamiona na cestama u RH Kilometar/sat | K13: Radno vrijeme vozača u satima | L13: Procjenjena ukupna prjeđena kilometraža dnevno za jedan kamion | M13: Procjenjena ukupna prijeđena kilometraža svih kamiona dnevno | N13: Procjenjena ukupna prijeđena kilometraža svih kamiona mjesečno
B14: Transport robe (unutar granica RH) | C14: € / km | D14: 1.42 | E14: =N14 -> 72000 | F14: =D14*E14 -> 102240 | G14: =F14*C8 -> 1226880 | I14: 5 | J14: 60 | K14: 8 | L14: =J14*K14 -> 480 | M14: =I14*L14 -> 2400 | N14: =M14*C7 -> 72000
B17: 2026. GODINA | I17: Kalkulacija prihoda transporta robe unutar granica RH 2026.
B19: Usluga | C19: Jedinica mjere | D19: Jedinična cijena | E19: Količina | F19: Ukupni mjesečni prihod | G19: Ukupni godišnji prihod | I19: Procjenjen broj produktivnih kamiona dnevno (na temelju pretpostavke o potražnji za našim uslugama) | J19: Prosječna brzina kamiona na cestama u RH Kilometar/sat | K19: Radno vrijeme vozača u satima | L19: Procjenjena ukupna prjeđena kilometraža dnevno za jedan kamion | M19: Procjenjena ukupna prijeđena kilometraža svih kamiona dnevno | N19: Procjenjena ukupna prijeđena kilometraža svih kamiona mjesečno
B20: Transport robe (unutar granica RH) | C20: € / km | D20: 1.42 | E20: =N20 -> 72000 | F20: =D20*E20 -> 102240 | G20: =F20*C8 -> 1226880 | I20: 5 | J20: 60 | K20: 8 | L20: =J20*K20 -> 480 | M20: =I20*L20 -> 2400 | N20: =M20*C7 -> 72000
B23: 2027. GODINA | I23: Kalkulacija prihoda transporta robe unutar granica RH 2027.
B25: Usluga | C25: Jedinica mjere | D25: Jedinična cijena | E25: Količina | F25: Ukupni mjesečni prihod | G25: Ukupni godišnji prihod | I25: Procjenjen broj produktivnih kamiona dnevno (na temelju pretpostavke o potražnji za našim uslugama) | J25: Prosječna brzina kamiona na cestama u RH Kilometar/sat | K25: Radno vrijeme vozača u satima | L25: Procjenjena ukupna prjeđena kilometraža dnevno za jedan kamion | M25: Procjenjena ukupna prijeđena kilometraža svih kamiona dnevno | N25: Procjenjena ukupna prijeđena kilometraža svih kamiona mjesečno
B26: Transport robe (unutar granica RH) | C26: € / km | D26: 1.47 | E26: =N26 -> 86400 | F26: =D26*E26 -> 127008 | G26: =F26*C8 -> 1524096 | I26: 6 | J26: 60 | K26: 8 | L26: =J26*K26 -> 480 | M26: =I26*L26 -> 2880 | N26: =M26*C7 -> 86400
B29: 2028. GODINA | I29: Kalkulacija prihoda transporta robe unutar granica RH 2028.
B31: Usluga | C31: Jedinica mjere | D31: Jedinična cijena | E31: Količina | F31: Ukupni mjesečni prihod | G31: Ukupni godišnji prihod | I31: Procjenjen broj produktivnih kamiona dnevno (na temelju pretpostavke o potražnji za našim uslugama) | J31: Prosječna brzina kamiona na cestama u RH Kilometar/sat | K31: Radno vrijeme vozača u satima | L31: Procjenjena ukupna prjeđena kilometraža dnevno za jedan kamion | M31: Procjenjena ukupna prijeđena kilometraža svih kamiona dnevno | N31: Procjenjena ukupna prijeđena kilometraža svih kamiona mjesečno
B32: Transport robe (unutar granica RH) | C32: € / km | D32: 1.5 | E32: =N32 -> 100800 | F32: =D32*E32 -> 151200 | G32: =F32*C8 -> 1814400 | I32: 7 | J32: 60 | K32: 8 | L32: =J32*K32 -> 480 | M32: =I32*L32 -> 3360 | N32: =M32*C7 -> 100800
B35: 2029. GODINA | I35: Kalkulacija prihoda transporta robe unutar granica RH 2029.
B37: Usluga | C37: Jedinica mjere | D37: Jedinična cijena | E37: Količina | F37: Ukupni mjesečni prihod | G37: Ukupni godišnji prihod | I37: Procjenjen broj produktivnih kamiona dnevno (na temelju pretpostavke o potražnji za našim uslugama) | J37: Prosječna brzina kamiona na cestama u RH Kilometar/sat | K37: Radno vrijeme vozača u satima | L37: Procjenjena ukupna prjeđena kilometraža dnevno za jedan kamion | M37: Procjenjena ukupna prijeđena kilometraža svih kamiona dnevno | N37: Procjenjena ukupna prijeđena kilometraža svih kamiona mjesečno
B38: Transport robe (unutar granica RH) | C38: € / km | D38: 1.55 | E38: =N38 -> 129600 | F38: =D38*E38 -> 200880 | G38: =F38*C8 -> 2410560 | I38: 9 | J38: 60 | K38: 8 | L38: =J38*K38 -> 480 | M38: =I38*L38 -> 4320 | N38: =M38*C7 -> 129600
B41: 2030. - 2034. GODINA | I41: Kalkulacija prihoda transporta robe unutar granica RH 2030. - 2034.
B43: Usluga | C43: Jedinica mjere | D43: Jedinična cijena | E43: Količina | F43: Ukupni mjesečni prihod | G43: Ukupni godišnji prihod | I43: Procjenjen broj produktivnih kamiona dnevno (na temelju pretpostavke o potražnji za našim uslugama) | J43: Prosječna brzina kamiona na cestama u RH Kilometar/sat | K43: Radno vrijeme vozača u satima | L43: Procjenjena ukupna prjeđena kilometraža dnevno za jedan kamion | M43: Procjenjena ukupna prijeđena kilometraža svih kamiona dnevno | N43: Procjenjena ukupna prijeđena kilometraža svih kamiona mjesečno
B44: Transport robe (unutar granica RH) | C44: € / km | D44: 1.57 | E44: =N44 -> 144000 | F44: =D44*E44 -> 226080 | G44: =F44*C8 -> 2712960 | I44: 10 | J44: 60 | K44: 8 | L44: =J44*K44 -> 480 | M44: =I44*L44 -> 4800 | N44: =M44*C7 -> 144000

Sheet Rashodi
B2: RASHODI KROZ GODINE RADA PROJEKTA
B4: GODINA | C4: 2025 | D4: 2026 | E4: 2027 | F4: 2028 | G4: 2029 | H4: 2030 | I4: 2031 | J4: 2032 | K4: 2033 | L4: 2034
B5: Trošak goriva za teretna vozila | C5: =G21 -> 311247.36 | D5: =G41 -> 311247.36 | E5: =G60 -> 373496.83 | F5: =G79 -> 435746.3 | G5: =G98 -> 560245.25 | H5: =$G$117 -> 622494.72 | I5: =$G$117 -> 622494.72 | J5: =$G$117 -> 622494.72 | K5: =$G$117 -> 622494.72 | L5: =$G$117 -> 622494.72
B6: Trošak registracije, tehničkog pregleda, osiguranja i servisa teretnih i priključnih vozila | C6: =SUM(G22:G24) -> 498000 | D6: =SUM(G42:G44) -> 498000 | E6: =SUM(G61:G63) -> 498000 | F6: =SUM(G80:G82) -> 498000 | G6: =SUM(G99:G101) -> 498000 | H6: =SUM($G$118:$G$121) -> 705360 | I6: =SUM($G$118:$G$121) -> 705360 | J6: =SUM($G$118:$G$121) -> 705360 | K6: =SUM($G$118:$G$121) -> 705360 | L6: =SUM($G$118:$G$121) -> 705360
B7: Troškovi autoguma (za teretna i priključna vozila) | C7: =SUM(G27:G28) -> 44928 | D7: =SUM(G47:G48) -> 44928 | E7: =SUM(G66:G67) -> 53913.6 | F7: =SUM(G85:G86) -> 62899.2 | G7: =SUM(G104:G105) -> 80870.4 | H7: =SUM($G$124:$G$125) -> 89856 | I7: =SUM($G$124:$G$125) -> 89856 | J7: =SUM($G$124:$G$125) -> 89856 | K7: =SUM($G$124:$G$125) -> 89856 | L7: =SUM($G$124:$G$125) -> 89856
B8: Mazut i motorna ulja | C8: =SUM(G25:G26) -> 11232 | D8: =SUM(G45:G46) -> 11232 | E8: =SUM(G64:G65) -> 13478.4 | F8: =SUM(G83:G84) -> 15724.8 | G8: =SUM(G102:G103) -> 20217.6 | H8: =SUM($G$122:$G$123) -> 22464 | I8: =SUM($G$122:$G$123) -> 22464 | J8: =SUM($G$122:$G$123) -> 22464 | K8: =SUM($G$122:$G$123) -> 22464 | L8: =SUM($G$122:$G$123) -> 22464
B9: Potrošena energija u administraciji, upravi, prodaji | C9: =SUM(G29:G31) -> 11219.194 | D9: =SUM(G49:G51) -> 11219.194 | E9: =SUM(G68:G70) -> 11219.194 | F9: =SUM(G87:G89) -> 11219.194 | G9: =SUM(G106:G108) -> 11219.194 | H9: =SUM($G$126:$G$128) -> 11219.194 | I9: =SUM($G$126:$G$128) -> 11219.194 | J9: =SUM($G$126:$G$128) -> 11219.194 | K9: =SUM($G$126:$G$128) -> 11219.194 | L9: =SUM($G$126:$G$128) -> 11219.194
B10: Uredski materijal | C10: =SUM(G32) -> 600 | D10: =SUM(G52) -> 600 | E10: =SUM(G71) -> 600 | F10: =SUM(G90) -> 600 | G10: =SUM(G109) -> 600 | H10: =SUM($G$90) -> 600 | I10: =SUM($G$90) -> 600 | J10: =SUM($G$90) -> 600 | K10: =SUM($G$90) -> 600 | L10: =SUM($G$90) -> 600
B11: UKUPNI RASHODI | C11: =SUM(C5:C10) -> 877226.55 | D11: =SUM(D5:D10) -> 877226.55 | E11: =SUM(E5:E10) -> 950708.03 | F11: =SUM(F5:F10) -> 1024189.5 | G11: =SUM(G5:G10) -> 1171152.4 | H11: =SUM(H5:H10) -> 1451993.9 | I11: =SUM(I5:I10) -> 1451993.9 | J11: =SUM(J5:J10) -> 1451993.9 | ... L11: =SUM(L5:L10) -> 1451993.9
B14: Broj dana u mjesecu | C14: 30
B15: Mjeseci u godini | C15: 12
B18: 2025. GODINA | I18: Kalkulacija troška goriva za transport robe unutar granica RH 2025.
B20: Opis | C20: Jedinica mjere | D20: Jedinična cijena | E20: Količina | F20: Ukupni mjesečni trošak | G20: Ukupni godišnji trošak | I20: Procjenjen broj produktivnih kamiona dnevno (na temelju pretpostavke o potražnji za našim uslugama) | J20: Prosječna brzina kamiona na cestama u RH Kilometar/sat | K20: Radno vrijeme vozača u satima | L20: Procjenjena ukupna prjeđena kilometraža dnevno za jedan kamion | M20: Procjenjena ukupna prijeđena kilometraža svih kamiona dnevno | N20: Procjenjena ukupna prijeđena kilometraža svih kamiona mjesečno | O20: Prosječna potrošnja nabavljenih kamiona s maksimalnim kapacitetom popunjenosti prikolice L/100 km | P20: Medijan cijene dizela za "INA – Industrija nafte d.d." na dan 2.2.2024. bez PDV-a (trošarine uključene) | Q20: Ukupna mjesečna potrošnja litara svih kamiona L | R20: Procjenjen ukupni mjesečni trošak goriva svih kamiona
B21: Trošak goriva za teretna vozila | C21: L | D21: =P21 -> 1.14 | E21: =Q21 -> 22752 | F21: =R21 -> 25937.28 | G21: =F21*$C$15 -> 311247.36 | I21: 5 | J21: 60 | K21: 8 | L21: =K21*J21 -> 480 | M21: =I21*L21 -> 2400 | N21: =M21*$C$14 -> 72000 | O21: 31.6 | P21: 1.14 | Q21: =(N21*O21)/100 -> 22752 | R21: =P21*Q21 -> 25937.28
B22: Registracija i tehnički pregled kamiona i prikolice | C22: Kom | D22: 500 | E22: 10 | F22: =D22*E22 -> 5000 | G22: =F22*$C$15 -> 60000
B23: Registracija i tehnički pregled prikolice | C23: Kom | D23: 500 | E23: 13 | F23: =E23*D23 -> 6500 | G23: =F23*$C$15 -> 78000
B24: Kasko osiguranje kamiona | C24: Kom | D24: 3000 | E24: 10 | F24: =E24*D24 -> 30000 | G24: =F24*$C$15 -> 360000
B25: Ulje, podmazivači | C25: 100 Km | D25: 0.75 | E25: =N21/100 -> 720 | F25: =E25*D25 -> 540 | G25: =F25*$C$15 -> 6480
B26: Punjenje addBlue tekućine | C26: 100 Km | D26: 0.55 | E26: =N21/100 -> 720 | F26: =E26*D26 -> 396 | G26: =F26*$C$15 -> 4752
B27: Gume: prednje i pogonske osovine | C27: 100 Km | D27: 2.47 | E27: =N21/100 -> 720 | F27: =E27*D27 -> 1778.4 | G27: =F27*$C$15 -> 21340.8
B28: Gume prikolica | C28: 100 Km | D28: 2.73 | E28: =N21/100 -> 720 | F28: =E28*D28 -> 1965.6 | G28: =F28*$C$15 -> 23587.2
B29: Troškovi električne energija | C29: kWh | D29: 0.2 | E29: 3120 | F29: =E29*D29 -> 624 | G29: =F29*$C$15 -> 7488
B30: Trošak vode i odvodnje | C30: m3 | D30: 2.2 | E30: 5 | F30: =D30*E30 -> 11 | G30: =F30*$C$15 -> 132
B31: Trošak plina | C31: kWh | D31: 7.96 | E31: 37.68 | F31: =D31*E31 -> 299.9328 | G31: =F31*$C$15 -> 3599.1936
B32: Trošak uredskog materijala | C32: / | D32: / | E32: / | F32: 50 | G32: =F32*$C$15 -> 600
E33: UKUPNO | F33: =SUM(F21:F32) -> 73102.213 | G33: =SUM(G21:G32) -> 877226.55
B38: 2026. GODINA | I38: Kalkulacija troška goriva za transport robe unutar granica RH 2026.
B40: Opis | C40: Jedinica mjere | D40: Jedinična cijena | E40: Količina | F40: Ukupni mjesečni trošak | G40: Ukupni godišnji trošak | I40: Procjenjen broj produktivnih kamiona dnevno (na temelju pretpostavke o potražnji za našim uslugama) | J40: Prosječna brzina kamiona na cestama u RH Kilometar/sat | K40: Radno vrijeme vozača u satima | L40: Procjenjena ukupna prjeđena kilometraža dnevno za jedan kamion | M40: Procjenjena ukupna prijeđena kilometraža svih kamiona dnevno | N40: Procjenjena ukupna prijeđena kilometraža svih kamiona mjesečno | O40: Prosječna potrošnja nabavljenih kamiona s maksimalnim kapacitetom popunjenosti prikolice L/100 km | P40: Najviša cijena goriva u RH u posljednjih 10 godina (najgori mogući scenarij) | Q40: Ukupna mjesečna potrošnja litara svih kamiona L | R40: Procjenjen ukupni mjesečni trošak goriva svih kamiona
B41: Trošak goriva za teretna vozila | C41: L | D41: =P41 -> 1.14 | E41: =Q41 -> 22752 | F41: =R41 -> 25937.28 | G41: =F41*$C$15 -> 311247.36 | I41: 5 | J41: 60 | K41: 8 | L41: =K41*J41 -> 480 | M41: =I41*L41 -> 2400 | N41: =M41*$C$14 -> 72000 | O41: 31.6 | P41: 1.14 | Q41: =(N41*O41)/100 -> 22752 | R41: =P41*Q41 -> 25937.28
B42: Registracija i tehnički pregled kamiona i prikolice | C42: Kom | D42: 500 | E42: 10 | F42: =D42*E42 -> 5000 | G42: =F42*$C$15 -> 60000
B43: Registracija i tehnički pregled prikolice | C43: Kom | D43: 500 | E43: 13 | F43: =E43*D43 -> 6500 | G43: =F43*$C$15 -> 78000
B44: Kasko osiguranje kamiona | C44: Kom | D44: 3000 | E44: 10 | F44: =E44*D44 -> 30000 | G44: =F44*$C$15 -> 360000
B45: Ulje, podmazivači | C45: 100 Km | D45: 0.75 | E45: =N41/100 -> 720 | F45: =E45*D45 -> 540 | G45: =F45*$C$15 -> 6480
B46: Punjenje addBlue tekućine | C46: 100 Km | D46: 0.55 | E46: =N41/100 -> 720 | F46: =E46*D46 -> 396 | G46: =F46*$C$15 -> 4752
B47: Gume: prednje i pogonske osovine | C47: 100 Km | D47: 2.47 | E47: =N41/100 -> 720 | F47: =E47*D47 -> 1778.4 | G47: =F47*$C$15 -> 21340.8
B48: Gume prikolica | C48: 100 Km | D48: 2.73 | E48: =N41/100 -> 720 | F48: =E48*D48 -> 1965.6 | G48: =F48*$C$15 -> 23587.2
B49: Troškovi električne energija | C49: kWh | D49: 0.2 | E49: 3120 | F49: =E49*D49 -> 624 | G49: =F49*$C$15 -> 7488
B50: Trošak vode i odvodnje | C50: m3 | D50: 2.2 | E50: 5 | F50: =D50*E50 -> 11 | G50: =F50*$C$15 -> 132
B51: Trošak plina | C51: kWh | D51: 7.96 | E51: 37.68 | F51: =D51*E51 -> 299.9328 | G51: =F51*$C$15 -> 3599.1936
B52: Trošak uredskog materijala | C52: / | D52: / | E52: / | F52: 50 | G52: =F52*$C$15 -> 600
...

Sheet Plaće
B2: OBRAČUN PLAĆA
D4: Plaća nositelja društva | E4: Plaća vozača kamiona
B5: Bruto plaća | D5: 2950 | E5: 1746.87
B6: I. stupanj mirovinskog osiguranja | C6: 0.15 | D6: =D5*$C$6 -> 442.5 | E6: =E5*$C$6 -> 262.0305
B7: II. stupanj mirovinskog osiguranja | C7: 0.05 | D7: =D5*$C$7 -> 147.5 | E7: =E5*$C$7 -> 87.3435
B8: Dohodak | D8: =D5-D6-D7 -> 2360 | E8: =E5-E6-E7 -> 1397.496
B9: Osobni odbitak | D9: 560 | E9: 560
B10: Porezna osnovica | D10: =D8-D9 -> 1800 | E10: =E8-E9 -> 837.496
B11: Porez na dohodak | C11: 0.2 | D11: =D10*$C$11 -> 360 | E11: =E10*$C$11 -> 167.4992
B12: Doprinos za zdravstveno osiguranje | C12: 0.165 | D12: =D5*$C$12 -> 486.75 | E12: =E5*$C$12 -> 288.23355
B13: Neto plaća | D13: =D8-D11 -> 2000 | E13: =E8-E11 -> 1229.9968
B14: UKUPNI TROŠAK PLAĆE | D14: =D5+D12 -> 3436.75 | E14: =E5+E12 -> 2035.1035
B17: GODIŠNJE PLAĆE ZAPOSLENIKA
B19: GODINA | C19: 2025 | D19: 2026 | E19: 2027 | F19: 2028 | G19: 2029 | H19: 2030 | I19: 2031 | J19: 2032 | K19: 2033 | L19: 2034
B20: BROJ VOZAČA KAMIONA | C20: 10 | D20: 10 | E20: 12 | F20: 14 | G20: 18 | H20: 20 | I20: 20 | J20: 20 | K20: 20 | L20: 20
B21: BROJ ZAPOSLENIKA ADMINISTRACIJE | C21: 3 | D21: 3 | E21: 3 | F21: 3 | G21: 3 | H21: 3 | I21: 3 | J21: 3 | K21: 3 | L21: 3
B22: MJESEČNI TROŠAK PLAĆA | C22: =(C20*$E$14)+(C21*$D$14) -> 30661.285 | D22: =(D20*$E$14)+(D21*$D$14) -> 30661.285 | E22: =(E20*$E$14)+(E21*$D$14) -> 34731.493 | F22: =(F20*$E$14)+(F21*$D$14) -> 38801.7 | G22: =(G20*$E$14)+(G21*$D$14) -> 46942.114 | H22: =(H20*$E$14)+(H21*$D$14) -> 51012.321 | I22: =(I20*$E$14)+(I21*$D$14) -> 51012.321 | J22: =(J20*$E$14)+(J21*$D$14) -> 51012.321 | ... L22: =(L20*$E$14)+(L21*$D$14) -> 51012.321
B23: GODIŠNJI TROŠAK PLAĆA | C23: =C22*$C$25 -> 367935.43 | D23: =D22*$C$25 -> 367935.43 | E23: =E22*$C$25 -> 416777.91 | F23: =F22*$C$25 -> 465620.4 | G23: =G22*$C$25 -> 563305.37 | H23: =H22*$C$25 -> 612147.85 | I23: =I22*$C$25 -> 612147.85 | J23: =J22*$C$25 -> 612147.85 | ... L23: =L22*$C$25 -> 612147.85
B25: Mjeseci u godini | C25: 12

Sheet Kredit
B2: Visina kredita | C2: ='In + Am'!F12 -> 500000
B3: Broj anuiteta | C3: 120
B4: Godišnja kamatna stopa | C4: 0.0375
B5: Broj ukamaćivanja godišnje | C5: 12
B6: Relativna kamatna stopa | C6: =C4/C5 -> 0.003125
B7: VISINA ANUITETA | C7: =PMT(C4/12,C3,C2)*-1 -> 5003.0622
B10: GODINE | C10: 1 | D10: 2 | E10: 3 | F10: 4 | G10: 5 | H10: 6 | I10: 7 | J10: 8 | K10: 9 | L10: 10 | M10: UKUPNO
B11: Kamate | C11: =SUM(D21:D32) -> 18032.94 | D11: =SUM(D33:D44) -> 16430.44 | E11: =SUM(D45:D56) -> 14766.804 | F11: =SUM(D57:D68) -> 13039.697 | G11: =SUM(D69:D80) -> 11246.699 | H11: =SUM(D81:D92) -> 9385.2952 | I11: =SUM(D93:D104) -> 7452.8769 | J11: =SUM(D105:D116) -> 5446.7343 | K11: =SUM(D117:D128) -> 3364.0548 | L11: =SUM(D129:D140) -> 1201.9184 | M11: =SUM(C11:L11) -> 100367.46
B12: Otplata | C12: =SUM(E21:E32) -> 42003.806 | D12: =SUM(E33:E44) -> 43606.305 | E12: =SUM(E45:E56) -> 45269.942 | F12: =SUM(E57:E68) -> 46997.049 | G12: =SUM(E69:E80) -> 48790.047 | H12: =SUM(E81:E92) -> 50651.451 | I12: =SUM(E93:E104) -> 52583.869 | J12: =SUM(E105:E116) -> 54590.012 | K12: =SUM(E117:E128) -> 56672.691 | L12: =SUM(E129:E140) -> 58834.827 | M12: =SUM(C12:L12) -> 500000
B13: UKUPNO | C13: =SUM(C11:C12) -> 60036.746 | D13: =SUM(D11:D12) -> 60036.746 | E13: =SUM(E11:E12) -> 60036.746 | F13: =SUM(F11:F12) -> 60036.746 | G13: =SUM(G11:G12) -> 60036.746 | H13: =SUM(H11:H12) -> 60036.746 | I13: =SUM(I11:I12) -> 60036.746 | J13: =SUM(J11:J12) -> 60036.746 | ... L13: =SUM(L11:L12) -> 60036.746 | M13: =SUM(C13:L13) -> 600367.46
B16: OTPLATNA TABLICA
B19: Razdoblje | C19: Anuitet | D19: Kamate | E19: Otplatna Kvota | F19: Ostatak kredita
F20: =C2 -> 500000
B21: 1 | C21: =$C$7 -> 5003.0622 | D21: =F20*$C$6 -> 1562.5 | E21: =C21-D21 -> 3440.5622 | F21: =F20-E21 -> 496559.44
B22: 2 | C22: =$C$7 -> 5003.0622 | D22: =F21*$C$6 -> 1551.7482 | E22: =C22-D22 -> 3451.3139 | F22: =F21-E22 -> 493108.12
B23: 3 | C23: =$C$7 -> 5003.0622 | D23: =F22*$C$6 -> 1540.9629 | E23: =C23-D23 -> 3462.0993 | F23: =F22-E23 -> 489646.02
B24: 4 | C24: =$C$7 -> 5003.0622 | D24: =F23*$C$6 -> 1530.1438 | E24: =C24-D24 -> 3472.9183 | F24: =F23-E24 -> 486173.11
B25: 5 | C25: =$C$7 -> 5003.0622 | D25: =F24*$C$6 -> 1519.291 | E25: =C25-D25 -> 3483.7712 | F25: =F24-E25 -> 482689.34
B26: 6 | C26: =$C$7 -> 5003.0622 | D26: =F25*$C$6 -> 1508.4042 | E26: =C26-D26 -> 3494.658 | F26: =F25-E26 -> 479194.68
B27: 7 | C27: =$C$7 -> 5003.0622 | D27: =F26*$C$6 -> 1497.4834 | E27: =C27-D27 -> 3505.5788 | F27: =F26-E27 -> 475689.1
B28: 8 | C28: =$C$7 -> 5003.0622 | D28: =F27*$C$6 -> 1486.5284 | E28: =C28-D28 -> 3516.5337 | F28: =F27-E28 -> 472172.56
B29: 9 | C29: =$C$7 -> 5003.0622 | D29: =F28*$C$6 -> 1475.5393 | E29: =C29-D29 -> 3527.5229 | F29: =F28-E29 -> 468645.04
B30: 10 | C30: =$C$7 -> 5003.0622 | D30: =F29*$C$6 -> 1464.5158 | E30: =C30-D30 -> 3538.5464 | F30: =F29-E30 -> 465106.5
B31: 11 | C31: =$C$7 -> 5003.0622 | D31: =F30*$C$6 -> 1453.4578 | E31: =C31-D31 -> 3549.6044 | F31: =F30-E31 -> 461556.89
B32: 12 | C32: =$C$7 -> 5003.0622 | D32: =F31*$C$6 -> 1442.3653 | E32: =C32-D32 -> 3560.6969 | F32: =F31-E32 -> 457996.19
... B140: 120 | C140: =$C$7 -> 5003.0622 | D140: =F139*$C$6 -> 15.585863 | E140: =C140-D140 -> 4987.4763 | F140: =F139-E140 -> 6.4210326e-10

Sheet RDG
B2: RAČUN DOBITI I GUBITKA
B4: OPIS | C4: 2025 | D4: 2026 | E4: 2027 | F4: 2028 | G4: 2029 | H4: 2030 | I4: 2031 | J4: 2032 | K4: 2033 | L4: 2034
B5: Ukupni prihodi | C5: =C6 -> 1226880 | D5: =D6 -> 1226880 | E5: =E6 -> 1524096 | F5: =F6 -> 1814400 | G5: =G6 -> 2410560 | H5: =H6 -> 2712960 | I5: =I6 -> 2712960 | J5: =J6 -> 2712960 | ... L5: =L6 -> 2712960
B6: Prihodi od pruženih transportnih i špeditorskih usluga | C6: =Prihodi!C5 -> 1226880 | D6: =Prihodi!D5 -> 1226880 | E6: =Prihodi!E5 -> 1524096 | F6: =Prihodi!F5 -> 1814400 | G6: =Prihodi!G5 -> 2410560 | H6: =Prihodi!H5 -> 2712960 | I6: =Prihodi!I5 -> 2712960 | J6: =Prihodi!J5 -> 2712960 | ... L6: =Prihodi!L5 -> 2712960
B7: Operativni rashodi | C7: =SUM(C8:C11) -> 1245162 | D7: =SUM(D8:D11) -> 1245162 | E7: =SUM(E8:E11) -> 1367485.9 | F7: =SUM(F8:F11) -> 1489809.9 | G7: =SUM(G8:G11) -> 1734457.8 | H7: =SUM(H8:H11) -> 2064141.8 | I7: =SUM(I8:I11) -> 2064141.8 | J7: =SUM(J8:J11) -> 2064141.8 | ... L7: =SUM(L8:L11) -> 2064141.8
B8: Trošak sirovina i materijala | C8: =SUM(Rashodi!C5,Rashodi!C7:C8) -> 367407.36 | D8: =SUM(Rashodi!D5,Rashodi!D7:D8) -> 367407.36 | E8: =SUM(Rashodi!E5,Rashodi!E7:E8) -> 440888.83 | F8: =SUM(Rashodi!F5,Rashodi!F7:F8) -> 514370.3 | G8: =SUM(Rashodi!G5,Rashodi!G7:G8) -> 661333.25 | H8: =SUM(Rashodi!H5,Rashodi!H7:H8) -> 734814.72 | I8: =SUM(Rashodi!I5,Rashodi!I7:I8) -> 734814.72 | J8: =SUM(Rashodi!J5,Rashodi!J7:J8) -> 734814.72 | ... L8: =SUM(Rashodi!L5,Rashodi!L7:L8) -> 734814.72
B9: Energija | C9: =Rashodi!C9 -> 11219.194 | D9: =Rashodi!D9 -> 11219.194 | E9: =Rashodi!E9 -> 11219.194 | F9: =Rashodi!F9 -> 11219.194 | G9: =Rashodi!G9 -> 11219.194 | H9: =Rashodi!H9 -> 11219.194 | I9: =Rashodi!I9 -> 11219.194 | J9: =Rashodi!J9 -> 11219.194 | ... L9: =Rashodi!L9 -> 11219.194
B10: Ostali troškovi | C10: =SUM(Rashodi!C6,Rashodi!C10) -> 498600 | D10: =SUM(Rashodi!D6,Rashodi!D10) -> 498600 | E10: =SUM(Rashodi!E6,Rashodi!E10) -> 498600 | F10: =SUM(Rashodi!F6,Rashodi!F10) -> 498600 | G10: =SUM(Rashodi!G6,Rashodi!G10) -> 498600 | H10: =SUM(Rashodi!H6,Rashodi!H10) -> 705960 | I10: =SUM(Rashodi!I6,Rashodi!I10) -> 705960 | J10: =SUM(Rashodi!J6,Rashodi!J10) -> 705960 | ... L10: =SUM(Rashodi!L6,Rashodi!L10) -> 705960
B11: Trošak plaća | C11: =Plaće!C23 -> 367935.43 | D11: =Plaće!D23 -> 367935.43 | E11: =Plaće!E23 -> 416777.91 | F11: =Plaće!F23 -> 465620.4 | G11: =Plaće!G23 -> 563305.37 | H11: =Plaće!H23 -> 612147.85 | I11: =Plaće!I23 -> 612147.85 | J11: =Plaće!J23 -> 612147.85 | ... L11: =Plaće!L23 -> 612147.85
B12: EBITDA | C12: =C5-C7 -> -18281.98 | D12: =D5-D7 -> -18281.98 | E12: =E5-E7 -> 156610.06 | F12: =F5-F7 -> 324590.11 | G12: =G5-G7 -> 676102.19 | H12: =H5-H7 -> 648818.23 | I12: =I5-I7 -> 648818.23 | J12: =J5-J7 -> 648818.23 | ... L12: =L5-L7 -> 648818.23
B13: Amortizacija | C13: ='In + Am'!F38 -> 609960.64 | D13: ='In + Am'!G38 -> 609960.64 | E13: ='In + Am'!H38 -> 608630.87 | F13: ='In + Am'!I38 -> 608630.87 | G13: ='In + Am'!J38 -> 46851.201 | H13: ='In + Am'!K38 -> 46851.201 | I13: ='In + Am'!L38 -> 46851.201 | J13: ='In + Am'!M38 -> 46851.201 | ... L13: ='In + Am'!O38 -> 46851.201
B14: Kamate | C14: =Kredit!C11 -> 18032.94 | D14: =Kredit!D11 -> 16430.44 | E14: =Kredit!E11 -> 14766.804 | F14: =Kredit!F11 -> 13039.697 | G14: =Kredit!G11 -> 11246.699 | H14: =Kredit!H11 -> 9385.2952 | I14: =Kredit!I11 -> 7452.8769 | J14: =Kredit!J11 -> 5446.7343 | ... L14: =Kredit!L11 -> 1201.9184
B15: Ukupni rashodi | C15: =C7+C13+C14 -> 1873155.6 | D15: =D7+D13+D14 -> 1871553.1 | E15: =E7+E13+E14 -> 1990883.6 | F15: =F7+F13+F14 -> 2111480.5 | G15: =G7+G13+G14 -> 1792555.7 | H15: =H7+H13+H14 -> 2120378.3 | I15: =I7+I13+I14 -> 2118445.8 | J15: =J7+J13+J14 -> 2116439.7 | ... L15: =L7+L13+L14 -> 2112194.9
B16: Bruto dobit/gubitak | C16: =C12-C13-C14 -> -646275.56 | D16: =D12-D13-D14 -> -644673.06 | E16: =E12-E13-E14 -> -466787.61 | F16: =F12-F13-F14 -> -297080.46 | G16: =G12-G13-G14 -> 618004.29 | H16: =H12-H13-H14 -> 592581.74 | I16: =I12-I13-I14 -> 594514.16 | J16: =J12-J13-J14 -> 596520.3 | ... L16: =L12-L13-L14 -> 600765.12
B17: Porez | C17: =IF(C16<0, 0, C16*$C$20) -> 0 | D17: =IF(D16<0, 0, D16*$C$20) -> 0 | E17: =IF(E16<0, 0, E16*$C$20) -> 0 | F17: =IF(F16<0, 0, F16*$C$20) -> 0 | G17: =IF(G16<0, 0, G16*$C$20) -> 61800.429 | H17: =IF(H16<0, 0, H16*$C$20) -> 59258.174 | I17: =IF(I16<0, 0, I16*$C$20) -> 59451.416 | J17: =IF(J16<0, 0, J16*$C$20) -> 59652.03 | ... L17: =IF(L16<0, 0, L16*$C$20) -> 60076.512
B18: NETO DOBIT/GUBITAK | C18: =C16-C17 -> -646275.56 | D18: =D16-D17 -> -644673.06 | E18: =E16-E17 -> -466787.61 | F18: =F16-F17 -> -297080.46 | G18: =G16-G17 -> 556203.86 | H18: =H16-H17 -> 533323.56 | I18: =I16-I17 -> 535062.74 | J18: =J16-J17 -> 536868.27 | ... L18: =L16-L17 -> 540688.6
B20: Porez na dobit | C20: 0.1

Sheet TOBS
B2: POTREBAN TOBS
B4: Stavka | C4: DV | D4: KO | E4: Ukupna svota
E5: 2025 | F5: 2026 | G5: 2027 | H5: 2028 | I5: 2029 | J5: 2030 | K5: 2031 | L5: 2032 | M5: 2033 | N5: 2034
B6: Zalihe sirovina i materijala | C6: 20 | D6: =360/C6 -> 18 | E6: =RDG!C8 -> 367407.36 | F6: =RDG!D8 -> 367407.36 | G6: =RDG!E8 -> 440888.83 | H6: =RDG!F8 -> 514370.3 | I6: =RDG!G8 -> 661333.25 | J6: =RDG!H8 -> 734814.72 | K6: =RDG!I8 -> 734814.72 | L6: =RDG!J8 -> 734814.72 | ... N6: =RDG!L8 -> 734814.72
B7: Potraživanja od kupaca | C7: 15 | D7: =360/C7 -> 24 | E7: =RDG!C5 -> 1226880 | F7: =RDG!D5 -> 1226880 | G7: =RDG!E5 -> 1524096 | H7: =RDG!F5 -> 1814400 | I7: =RDG!G5 -> 2410560 | J7: =RDG!H5 -> 2712960 | K7: =RDG!I5 -> 2712960 | L7: =RDG!J5 -> 2712960 | ... N7: =RDG!L5 -> 2712960
B8: Novac u banci i blagajni | C8: 3 | D8: =360/C8 -> 120 | E8: =E7 -> 1226880 | F8: =F7 -> 1226880 | G8: =G7 -> 1524096 | H8: =H7 -> 1814400 | I8: =I7 -> 2410560 | J8: =J7 -> 2712960 | K8: =K7 -> 2712960 | L8: =L7 -> 2712960 | ... N8: =N7 -> 2712960
B10: Dobavljači | C10: 30 | D10: =360/C10 -> 12 | E10: =SUM(RDG!C8:C10) -> 877226.55 | F10: =SUM(RDG!D8:D10) -> 877226.55 | G10: =SUM(RDG!E8:E10) -> 950708.03 | H10: =SUM(RDG!F8:F10) -> 1024189.5 | I10: =SUM(RDG!G8:G10) -> 1171152.4 | J10: =SUM(RDG!H8:H10) -> 1451993.9 | K10: =SUM(RDG!I8:I10) -> 1451993.9 | L10: =SUM(RDG!J8:J10) -> 1451993.9 | ... N10: =SUM(RDG!L8:L10) -> 1451993.9
B11: Troškovi osoblja | C11: 30 | D11: =360/C11 -> 12 | E11: =RDG!C11 -> 367935.43 | F11: =RDG!D11 -> 367935.43 | G11: =RDG!E11 -> 416777.91 | H11: =RDG!F11 -> 465620.4 | I11: =RDG!G11 -> 563305.37 | J11: =RDG!H11 -> 612147.85 | K11: =RDG!I11 -> 612147.85 | L11: =RDG!J11 -> 612147.85 | ... N11: =RDG!L11 -> 612147.85
B12: Rashodi financiranja | C12: 30 | D12: =360/C12 -> 12 | E12: =RDG!C14 -> 18032.94 | F12: =RDG!D14 -> 16430.44 | G12: =RDG!E14 -> 14766.804 | H12: =RDG!F14 -> 13039.697 | I12: =RDG!G14 -> 11246.699 | J12: =RDG!H14 -> 9385.2952 | K12: =RDG!I14 -> 7452.8769 | L12: =RDG!J14 -> 5446.7343 | ... N12: =RDG!L14 -> 1201.9184
B13: Porez na dobit | C13: 30 | D13: =360/C13 -> 12 | E13: =RDG!C17 -> 0 | F13: =RDG!D17 -> 0 | G13: =RDG!E17 -> 0 | H13: =RDG!F17 -> 0 | I13: =RDG!G17 -> 61800.429 | J13: =RDG!H17 -> 59258.174 | K13: =RDG!I17 -> 59451.416 | L13: =RDG!J17 -> 59652.03 | ... N13: =RDG!L17 -> 60076.512
B16: POTREBAN TOBS
B18: Stavka | C18: DV | D18: KO | E18: Potreban iznos
E19: 2025 | F19: 2026 | G19: 2027 | H19: 2028 | I19: 2029 | J19: 2030 | K19: 2031 | L19: 2032 | M19: 2033 | N19: 2034
B20: Zalihe sirovina i materijala | C20: =C6 -> 20 | D20: =360/C20 -> 18 | E20: =E6/$D$6 -> 20411.52 | F20: =F6/$D$6 -> 20411.52 | G20: =G6/$D$6 -> 24493.824 | H20: =H6/$D$6 -> 28576.128 | I20: =I6/$D$6 -> 36740.736 | J20: =J6/$D$6 -> 40823.04 | K20: =K6/$D$6 -> 40823.04 | L20: =L6/$D$6 -> 40823.04 | ... N20: =N6/$D$6 -> 40823.04
B21: Potraživanja od kupaca | C21: =C7 -> 15 | D21: =360/C21 -> 24 | E21: =E7/$D$7 -> 51120 | F21: =F7/$D$7 -> 51120 | G21: =G7/$D$7 -> 63504 | H21: =H7/$D$7 -> 75600 | I21: =I7/$D$7 -> 100440 | J21: =J7/$D$7 -> 113040 | K21: =K7/$D$7 -> 113040 | L21: =L7/$D$7 -> 113040 | ... N21: =N7/$D$7 -> 113040
B22: Novac u banci i blagajni | C22: =C8 -> 3 | D22: =360/C22 -> 120 | E22: =E8/$D$8 -> 10224 | F22: =F8/$D$8 -> 10224 | G22: =G8/$D$8 -> 12700.8 | H22: =H8/$D$8 -> 15120 | I22: =I8/$D$8 -> 20088 | J22: =J8/$D$8 -> 22608 | K22: =K8/$D$8 -> 22608 | L22: =L8/$D$8 -> 22608 | ... N22: =N8/$D$8 -> 22608
B23: Ukupno potrebna sredstva | E23: =SUM(E20:E22) -> 81755.52 | F23: =SUM(F20:F22) -> 81755.52 | G23: =SUM(G20:G22) -> 100698.62 | H23: =SUM(H20:H22) -> 119296.13 | I23: =SUM(I20:I22) -> 157268.74 | J23: =SUM(J20:J22) -> 176471.04 | K23: =SUM(K20:K22) -> 176471.04 | L23: =SUM(L20:L22) -> 176471.04 | ... N23: =SUM(N20:N22) -> 176471.04
B24: Dobavljači | C24: =C10 -> 30 | D24: =360/C24 -> 12 | E24: =E10/$D$10 -> 73102.213 | F24: =F10/$D$10 -> 73102.213 | G24: =G10/$D$10 -> 79225.669 | H24: =H10/$D$10 -> 85349.125 | I24: =I10/$D$10 -> 97596.037 | J24: =J10/$D$10 -> 120999.49 | K24: =K10/$D$10 -> 120999.49 | L24: =L10/$D$10 -> 120999.49 | ... N24: =N10/$D$10 -> 120999.49
B25: Troškovi osoblja | C25: =C11 -> 30 | D25: =360/C25 -> 12 | E25: =E11/$D$11 -> 30661.285 | F25: =F11/$D$11 -> 30661.285 | G25: =G11/$D$11 -> 34731.493 | H25: =H11/$D$11 -> 38801.7 | I25: =I11/$D$11 -> 46942.114 | J25: =J11/$D$11 -> 51012.321 | K25: =K11/$D$11 -> 51012.321 | L25: =L11/$D$11 -> 51012.321 | ... N25: =N11/$D$11 -> 51012.321
B26: Rashodi financiranja | C26: =C12 -> 30 | D26: =360/C26 -> 12 | E26: =E12/$D$12 -> 1502.745 | F26: =F12/$D$12 -> 1369.2034 | G26: =G12/$D$12 -> 1230.567 | H26: =H12/$D$12 -> 1086.6414 | I26: =I12/$D$12 -> 937.22488 | J26: =J12/$D$12 -> 782.10794 | K26: =K12/$D$12 -> 621.07308 | L26: =L12/$D$12 -> 453.89453 | ... N26: =N12/$D$12 -> 100.15987
B27: Porez na dobit | C27: =C13 -> 30 | D27: =360/C27 -> 12 | E27: =E13/$D$13 -> 0 | F27: =F13/$D$13 -> 0 | G27: =G13/$D$13 -> 0 | H27: =H13/$D$13 -> 0 | I27: =I13/$D$13 -> 5150.0358 | J27: =J13/$D$13 -> 4938.1812 | K27: =K13/$D$13 -> 4954.2846 | L27: =L13/$D$13 -> 4971.0025 | ... N27: =N13/$D$13 -> 5006.376
B28: Izvori financiranja iz poslovanja | E28: =SUM(E24:E27) -> 105266.24 | F28: =SUM(F24:F27) -> 105132.7 | G28: =SUM(G24:G27) -> 115187.73 | H28: =SUM(H24:H27) -> 125237.47 | I28: =SUM(I24:I27) -> 150625.41 | J28: =SUM(J24:J27) -> 177732.1 | K28: =SUM(K24:K27) -> 177587.17 | L28: =SUM(L24:L27) -> 177436.71 | ... N28: =SUM(N24:N27) -> 177118.35
B29: Trajna obrtna sredstva | E29: =E23-E28 -> -23510.723 | F29: =F23-F28 -> -23377.182 | G29: =G23-G28 -> -14489.104 | H29: =H23-H28 -> -5941.3379 | I29: =I23-I28 -> 6643.3246 | J29: =J23-J28 -> -1261.0629 | K29: =K23-K28 -> -1116.1315 | L29: =L23-L28 -> -965.67082 | ... N29: =N23-N28 -> -647.30963
B30: Investicije u TOBS | E30: =E29-0 -> -23510.723 | F30: =F29-E29 -> 133.54162 | G30: =G29-F29 -> 8888.0773 | H30: =H29-G29 -> 8547.7665 | I30: =I29-H29 -> 12584.663 | J30: =J29-I29 -> -7904.3875 | K30: =K29-J29 -> 144.93137 | L30: =L29-K29 -> 150.46069 | M30: =M29-L29 -> 156.20096 | N30: =N29-M29 -> 162.16023

Sheet EK + FK
B2: EKONOMSKI TOK
B4: OPIS | C4: 2024 | D4: 2025 | E4: 2026 | F4: 2027 | G4: 2028 | H4: 2029 | I4: 2030 | J4: 2031 | K4: 2032 | L4: 2033 | M4: 2034
C5: 0 | D5: 1 | E5: 2 | F5: 3 | G5: 4 | H5: 5 | I5: 6 | J5: 7 | K5: 8 | L5: 9 | M5: 10
B6: I PRIMICI | C6: =SUM(C7:C8) -> 0 | D6: =SUM(D7:D8) -> 1226880 | E6: =SUM(E7:E8) -> 1226880 | F6: =SUM(F7:F8) -> 1524096 | G6: =SUM(G7:G8) -> 1814400 | H6: =SUM(H7:H8) -> 2410560 | I6: =SUM(I7:I8) -> 2712960 | J6: =SUM(J7:J8) -> 2712960 | ... M6: =SUM(M7:M8) -> 3180824.7
B7: 1. Ukupni prihod | D7: =RDG!C5 -> 1226880 | E7: =RDG!D5 -> 1226880 | F7: =RDG!E5 -> 1524096 | G7: =RDG!F5 -> 1814400 | H7: =RDG!G5 -> 2410560 | I7: =RDG!H5 -> 2712960 | J7: =RDG!I5 -> 2712960 | K7: =RDG!J5 -> 2712960 | ... M7: =RDG!L5 -> 2712960
B8: 2. Ostatak vrijednosti projekta | M8: =SUM(M9:M10) -> 467864.7
B9: 2.1. Osnovnih sredstava | M9: ='In + Am'!Q40 -> 468512
B10: 2.2. Obrtnih sredstava | M10: =TOBS!N29 -> -647.30963
B11: II IZDACI | C11: =SUM(C12:C16) -> 3186802.2 | D11: =SUM(D12:D16) -> 1221651.3 | E11: =SUM(E12:E16) -> 1245295.5 | F11: =SUM(F12:F16) -> 1376374 | G11: =SUM(G12:G16) -> 1498357.7 | H11: =SUM(H12:H16) -> 1808842.9 | I11: =SUM(I12:I16) -> 2115495.6 | J11: =SUM(J12:J16) -> 2123738.1 | ... M11: =SUM(M12:M16) -> 2124380.4
B12: 3. Angažirana OS | C12: ='In + Am'!D12 -> 3186802.2
B13: 4. Angažirana TOBS | C13: 0 | D13: =TOBS!E29 -> -23510.723 | E13: =TOBS!F29-TOBS!E29 -> 133.54162 | F13: =TOBS!G29-TOBS!F29 -> 8888.0773 | G13: =TOBS!H29-TOBS!G29 -> 8547.7665 | H13: =TOBS!I29-TOBS!H29 -> 12584.663 | I13: =TOBS!J29-TOBS!I29 -> -7904.3875 | J13: =TOBS!K29-TOBS!J29 -> 144.93137 | K13: =TOBS!L29-TOBS!K29 -> 150.46069 | L13: =TOBS!M29-TOBS!L29 -> 156.20096 | M13: =TOBS!N29-TOBS!M29 -> 162.16023
B14: 5. Troškovi održavanja i usluga | D14: =SUM(RDG!C8:C10) -> 877226.55 | E14: =SUM(RDG!D8:D10) -> 877226.55 | F14: =SUM(RDG!E8:E10) -> 950708.03 | G14: =SUM(RDG!F8:F10) -> 1024189.5 | H14: =SUM(RDG!G8:G10) -> 1171152.4 | I14: =SUM(RDG!H8:H10) -> 1451993.9 | J14: =SUM(RDG!I8:I10) -> 1451993.9 | K14: =SUM(RDG!J8:J10) -> 1451993.9 | ... M14: =SUM(RDG!L8:L10) -> 1451993.9
B15: 6. Izdaci za osoblje | D15: =RDG!C11 -> 367935.43 | E15: =RDG!D11 -> 367935.43 | F15: =RDG!E11 -> 416777.91 | G15: =RDG!F11 -> 465620.4 | H15: =RDG!G11 -> 563305.37 | I15: =RDG!H11 -> 612147.85 | J15: =RDG!I11 -> 612147.85 | K15: =RDG!J11 -> 612147.85 | ... M15: =RDG!L11 -> 612147.85
B16: 7. Porezi | D16: =RDG!C17 -> 0 | E16: =RDG!D17 -> 0 | F16: =RDG!E17 -> 0 | G16: =RDG!F17 -> 0 | H16: =RDG!G17 -> 61800.429 | I16: =RDG!H17 -> 59258.174 | J16: =RDG!I17 -> 59451.416 | K16: =RDG!J17 -> 59652.03 | ... M16: =RDG!L17 -> 60076.512
B17: III NETO PRIMICI | C17: =C6-C11 -> -3186802.2 | D17: =D6-D11 -> 5228.7437 | E17: =E6-E11 -> -18415.521 | F17: =F6-F11 -> 147721.99 | G17: =G6-G11 -> 316042.34 | H17: =H6-H11 -> 601717.1 | I17: =I6-I11 -> 597464.45 | J17: =J6-J11 -> 589221.89 | ... M17: =M6-M11 -> 1056444.3
B18: IV KUMULATIVNI NETO PRIMITCI | C18: =C17 -> -3186802.2 | D18: =C18+D17 -> -3181573.5 | E18: =D18+E17 -> -3199989 | F18: =E18+F17 -> -3052267 | G18: =F18+G17 -> -2736224.7 | H18: =G18+H17 -> -2134507.6 | I18: =H18+I17 -> -1537043.1 | J18: =I18+J17 -> -947821.23 | K18: =J18+K17 -> -358805.48 | ... M18: =L18+M17 -> 1286440.5
B21: IZRAČUN DISKONTIRANOG RAZDOBLJA POVRATA ULOŽENIH SREDSTAVA
B23: GODINA | C23: 2024 | D23: 2025 | E23: 2026 | F23: 2027 | G23: 2028 | H23: 2029 | I23: 2030 | J23: 2031 | K23: 2032 | L23: 2033 | M23: 2034
C24: 0 | D24: 1 | E24: 2 | F24: 3 | G24: 4 | H24: 5 | I24: 6 | J24: 7 | K24: 8 | L24: 9 | M24: 10
B25: DNT | C25: =C17*1/(1+$C$28)^C24 -> -3186802.2 | D25: =D17*1/(1+$C$28)^D24 -> 5039.753 | E25: =E17*1/(1+$C$28)^E24 -> -17108.337 | F25: =F17*1/(1+$C$28)^F24 -> 132275.93 | G25: =G17*1/(1+$C$28)^G24 -> 272767.64 | H25: =H17*1/(1+$C$28)^H24 -> 500555.03 | I25: =I17*1/(1+$C$28)^I24 -> 479052.86 | J25: =J17*1/(1+$C$28)^J24 -> 455367.61 | ... M25: =M17*1/(1+$C$28)^M24 -> 731081.06
B26: KOMULATIV DNT | C26: =C25 -> -3186802.2 | D26: =C26+D25 -> -3181762.5 | E26: =D26+E25 -> -3198870.8 | F26: =E26+F25 -> -3066594.9 | G26: =F26+G25 -> -2793827.2 | H26: =G26+H25 -> -2293272.2 | I26: =H26+I25 -> -1814219.3 | J26: =I26+J25 -> -1358851.7 | K26: =J26+K25 -> -920096.75 | ... M26: =L26+M25 -> 233727.02
B28: Diskontna stopa | C28: =Kredit!C4 -> 0.0375
B31: FINANCIJSKI TOK
B33: OPIS | C33: 2024 | D33: 2025 | E33: 2026 | F33: 2027 | G33: 2028 | H33: 2029 | I33: 2030 | J33: 2031 | K33: 2032 | L33: 2033 | M33: 2034
C34: 0 | D34: 1 | E34: 2 | F34: 3 | G34: 4 | H34: 5 | I34: 6 | J34: 7 | K34: 8 | L34: 9 | M34: 10
B35: I PRIMICI | C35: =SUM(C36:C37,C40) -> 3186802.2 | D35: =SUM(D36:D37,D40) -> 1226880 | E35: =SUM(E36:E37,E40) -> 1226880 | F35: =SUM(F36:F37,F40) -> 1524096 | G35: =SUM(G36:G37,G40) -> 1814400 | H35: =SUM(H36:H37,H40) -> 2410560 | I35: =SUM(I36:I37,I40) -> 2712960 | J35: =SUM(J36:J37,J40) -> 2712960 | ... M35: =SUM(M36:M37,M40) -> 3180824.7
B36: 1. Ukupni prihod | D36: =D7 -> 1226880 | E36: =E7 -> 1226880 | F36: =F7 -> 1524096 | G36: =G7 -> 1814400 | H36: =H7 -> 2410560 | I36: =I7 -> 2712960 | J36: =J7 -> 2712960 | K36: =K7 -> 2712960 | ... M36: =M7 -> 2712960
B37: 2. Izvori financiranja | C37: =SUM(C38:C39) -> 3186802.2
B38: 2.1. Vlastito ulaganje | C38: ='In + Am'!E12 -> 2686802.2
B39: 2.2. Kredit | C39: ='In + Am'!F12 -> 500000
B40: 3. Ostatak vrijednosti projekta | M40: =SUM(M41:M42) -> 467864.7
B41: 3.1. Osnovnih sredstava | M41: =M9 -> 468512
B42: 3.2. Obrtnih sredstava | M42: =M10 -> -647.30963
B43: II IZDACI | C43: =SUM(C44:C49) -> 3186802.2 | D43: =SUM(D44:D49) -> 1281688 | E43: =SUM(E44:E49) -> 1305332.3 | F43: =SUM(F44:F49) -> 1436410.8 | G43: =SUM(G44:G49) -> 1558394.4 | H43: =SUM(H44:H49) -> 1868879.6 | I43: =SUM(I44:I49) -> 2175532.3 | J43: =SUM(J44:J49) -> 2183774.9 | ... M43: =SUM(M44:M49) -> 2184417.2
B44: 4. Investicije u OS | C44: =C12 -> 3186802.2
B45: 5. Investicije u TOBS | C45: =C13 -> 0 | D45: =D13 -> -23510.723 | E45: =E13 -> 133.54162 | F45: =F13 -> 8888.0773 | G45: =G13 -> 8547.7665 | H45: =H13 -> 12584.663 | I45: =I13 -> -7904.3875 | J45: =J13 -> 144.93137 | ... M45: =M13 -> 162.16023
B46: 6. Troškovi održavanja i usluga | D46: =D14 -> 877226.55 | E46: =E14 -> 877226.55 | F46: =F14 -> 950708.03 | G46: =G14 -> 1024189.5 | H46: =H14 -> 1171152.4 | I46: =I14 -> 1451993.9 | J46: =J14 -> 1451993.9 | K46: =K14 -> 1451993.9 | ... M46: =M14 -> 1451993.9
B47: 7. Izdaci za osoblje | D47: =D15 -> 367935.43 | E47: =E15 -> 367935.43 | F47: =F15 -> 416777.91 | G47: =G15 -> 465620.4 | H47: =H15 -> 563305.37 | I47: =I15 -> 612147.85 | J47: =J15 -> 612147.85 | K47: =K15 -> 612147.85 | ... M47: =M15 -> 612147.85
B48: 8. Porezi | D48: =D16 -> 0 | E48: =E16 -> 0 | F48: =F16 -> 0 | G48: =G16 -> 0 | H48: =H16 -> 61800.429 | I48: =I16 -> 59258.174 | J48: =J16 -> 59451.416 | K48: =K16 -> 59652.03 | ... M48: =M16 -> 60076.512
B49: 9. Otplata (glavnica + kamate) | D49: =Kredit!C13 -> 60036.746 | E49: =Kredit!D13 -> 60036.746 | F49: =Kredit!E13 -> 60036.746 | G49: =Kredit!F13 -> 60036.746 | H49: =Kredit!G13 -> 60036.746 | I49: =Kredit!H13 -> 60036.746 | J49: =Kredit!I13 -> 60036.746 | K49: =Kredit!J13 -> 60036.746 | ... M49: =Kredit!L13 -> 60036.746
...

Sheet EK + FK - osjetljivost
B2: EKONOMSKI TOK PRILIKOM PROMJENE ULAZNIH VARIJABLI - ANALIZA OSJETLJIVOSTI
B4: OPIS | C4: 2024 | D4: 2025 | E4: 2026 | F4: 2027 | G4: 2028 | H4: 2029 | I4: 2030 | J4: 2031 | K4: 2032 | L4: 2033 | M4: 2034
C5: 0 | D5: 1 | E5: 2 | F5: 3 | G5: 4 | H5: 5 | I5: 6 | J5: 7 | K5: 8 | L5: 9 | M5: 10
B6: I PRIMICI | C6: =C8+C10 -> 0 | D6: =D8+D10 -> 1226880 | E6: =E8+E10 -> 1226880 | F6: =F8+F10 -> 1524096 | G6: =G8+G10 -> 1814400 | H6: =H8+H10 -> 2410560 | I6: =I8+I10 -> 2712960 | J6: =J8+J10 -> 2712960 | ... M6: =M8+M10 -> 3180824.7
B7: I PRIMICI (-5% PRIHODI) | C7: =SUM(C9:C10) -> 0 | D7: =SUM(D9:D10) -> 1165536 | E7: =SUM(E9:E10) -> 1165536 | F7: =SUM(F9:F10) -> 1447891.2 | G7: =SUM(G9:G10) -> 1723680 | H7: =SUM(H9:H10) -> 2290032 | I7: =SUM(I9:I10) -> 2577312 | J7: =SUM(J9:J10) -> 2577312 | ... M7: =SUM(M9:M10) -> 3045176.7
B8: 1. Ukupni prihod | D8: ='EK + FK'!D7 -> 1226880 | E8: ='EK + FK'!E7 -> 1226880 | F8: ='EK + FK'!F7 -> 1524096 | G8: ='EK + FK'!G7 -> 1814400 | H8: ='EK + FK'!H7 -> 2410560 | I8: ='EK + FK'!I7 -> 2712960 | J8: ='EK + FK'!J7 -> 2712960 | K8: ='EK + FK'!K7 -> 2712960 | ... M8: ='EK + FK'!M7 -> 2712960
B9: 1. Ukupni prihod (-5%) | D9: ='EK + FK'!D7-('EK + FK'!D7*5%) -> 1165536 | E9: ='EK + FK'!E7-('EK + FK'!E7*5%) -> 1165536 | F9: ='EK + FK'!F7-('EK + FK'!F7*5%) -> 1447891.2 | G9: ='EK + FK'!G7-('EK + FK'!G7*5%) -> 1723680 | H9: ='EK + FK'!H7-('EK + FK'!H7*5%) -> 2290032 | I9: ='EK + FK'!I7-('EK + FK'!I7*5%) -> 2577312 | J9: ='EK + FK'!J7-('EK + FK'!J7*5%) -> 2577312 | K9: ='EK + FK'!K7-('EK + FK'!K7*5%) -> 2577312 | ... M9: ='EK + FK'!M7-('EK + FK'!M7*5%) -> 2577312
B10: 2. Ostatak vrijednosti projekta | M10: =SUM(M11:M12) -> 467864.7
B11: 2.1. Osnovnih sredstava | M11: ='EK + FK'!M9 -> 468512
B12: 2.2. Obrtnih sredstava | M12: ='EK + FK'!M10 -> -647.30963
B13: II IZDACI | C13: =SUM(C15:C17,C19:C20) -> 3186802.2 | D13: =SUM(D15:D17,D19:D20) -> 1221651.3 | E13: =SUM(E15:E17,E19:E20) -> 1245295.5 | F13: =SUM(F15:F17,F19:F20) -> 1376374 | G13: =SUM(G15:G17,G19:G20) -> 1498357.7 | H13: =SUM(H15:H17,H19:H20) -> 1808842.9 | I13: =SUM(I15:I17,I19:I20) -> 2115495.6 | J13: =SUM(J15:J17,J19:J20) -> 2123738.1 | ... M13: =SUM(M15:M17,M19:M20) -> 2124380.4
B14: II IZDACI (+5% TROŠKOVI) | C14: =SUM(C15:C16,C18:C20) -> 3186802.2 | D14: =SUM(D15:D16,D18:D20) -> 1265512.6 | E14: =SUM(E15:E16,E18:E20) -> 1289156.8 | F14: =SUM(F15:F16,F18:F20) -> 1423909.4 | G14: =SUM(G15:G16,G18:G20) -> 1549567.1 | H14: =SUM(H15:H16,H18:H20) -> 1867400.5 | I14: =SUM(I15:I16,I18:I20) -> 2188095.2 | J14: =SUM(J15:J16,J18:J20) -> 2196337.8 | ... M14: =SUM(M15:M16,M18:M20) -> 2196980.1
B15: 3. Angažirana OS | C15: ='EK + FK'!C12 -> 3186802.2
B16: 4. Angažirana TOBS | C16: 0 | D16: ='EK + FK'!D13 -> -23510.723 | E16: ='EK + FK'!E13 -> 133.54162 | F16: ='EK + FK'!F13 -> 8888.0773 | G16: ='EK + FK'!G13 -> 8547.7665 | H16: ='EK + FK'!H13 -> 12584.663 | I16: ='EK + FK'!I13 -> -7904.3875 | J16: ='EK + FK'!J13 -> 144.93137 | K16: ='EK + FK'!K13 -> 150.46069 | ... M16: ='EK + FK'!M13 -> 162.16023
B17: 5. Troškovi održavanja i usluga | D17: ='EK + FK'!D14 -> 877226.55 | E17: ='EK + FK'!E14 -> 877226.55 | F17: ='EK + FK'!F14 -> 950708.03 | G17: ='EK + FK'!G14 -> 1024189.5 | H17: ='EK + FK'!H14 -> 1171152.4 | I17: ='EK + FK'!I14 -> 1451993.9 | J17: ='EK + FK'!J14 -> 1451993.9 | K17: ='EK + FK'!K14 -> 1451993.9 | ... M17: ='EK + FK'!M14 -> 1451993.9
B18: 5. Troškovi održavanja i usluga (+5%) | D18: ='EK + FK'!D14+('EK + FK'!D14*5%) -> 921087.88 | E18: ='EK + FK'!E14+('EK + FK'!E14*5%) -> 921087.88 | F18: ='EK + FK'!F14+('EK + FK'!F14*5%) -> 998243.43 | G18: ='EK + FK'!G14+('EK + FK'!G14*5%) -> 1075399 | H18: ='EK + FK'!H14+('EK + FK'!H14*5%) -> 1229710.1 | I18: ='EK + FK'!I14+('EK + FK'!I14*5%) -> 1524593.6 | J18: ='EK + FK'!J14+('EK + FK'!J14*5%) -> 1524593.6 | K18: ='EK + FK'!K14+('EK + FK'!K14*5%) -> 1524593.6 | ... M18: ='EK + FK'!M14+('EK + FK'!M14*5%) -> 1524593.6
B19: 6. Izdaci za osoblje | D19: ='EK + FK'!D15 -> 367935.43 | E19: ='EK + FK'!E15 -> 367935.43 | F19: ='EK + FK'!F15 -> 416777.91 | G19: ='EK + FK'!G15 -> 465620.4 | H19: ='EK + FK'!H15 -> 563305.37 | I19: ='EK + FK'!I15 -> 612147.85 | J19: ='EK + FK'!J15 -> 612147.85 | K19: ='EK + FK'!K15 -> 612147.85 | ... M19: ='EK + FK'!M15 -> 612147.85
B20: 7. Porezi | D20: ='EK + FK'!D16 -> 0 | E20: ='EK + FK'!E16 -> 0 | F20: ='EK + FK'!F16 -> 0 | G20: ='EK + FK'!G16 -> 0 | H20: ='EK + FK'!H16 -> 61800.429 | I20: ='EK + FK'!I16 -> 59258.174 | J20: ='EK + FK'!J16 -> 59451.416 | K20: ='EK + FK'!K16 -> 59652.03 | ... M20: ='EK + FK'!M16 -> 60076.512
B21: III NETO PRIMICI (-5% PRIHODI) | C21: =C7-C13 -> -3186802.2 | D21: =D7-D13 -> -56115.256 | E21: =E7-E13 -> -79759.521 | F21: =F7-F13 -> 71517.186 | G21: =G7-G13 -> 225322.34 | H21: =H7-H13 -> 481189.1 | I21: =I7-I13 -> 461816.45 | J21: =J7-J13 -> 453573.89 | ... M21: =M7-M13 -> 920796.26
B22: IV KUMULATIVNI NETO PRIMITCI (-5% PRIHODI) | C22: =C21 -> -3186802.2 | D22: =C22+D21 -> -3242917.5 | E22: =D22+E21 -> -3322677 | F22: =E22+F21 -> -3251159.8 | G22: =F22+G21 -> -3025837.5 | H22: =G22+H21 -> -2544648.4 | I22: =H22+I21 -> -2082831.9 | J22: =I22+J21 -> -1629258 | K22: =J22+K21 -> -1175890.3 | ... M22: =L22+M21 -> 198059.71
B24: III NETO PRIMICI (+5% TROŠKOVI) | C24: =C6-C14 -> -3186802.2 | D24: =D6-D14 -> -38632.584 | E24: =E6-E14 -> -62276.849 | F24: =F6-F14 -> 100186.58 | G24: =G6-G14 -> 264832.86 | H24: =H6-H14 -> 543159.48 | I24: =I6-I14 -> 524864.75 | J24: =J6-J14 -> 516622.19 | ... M24: =M6-M14 -> 983844.56
B25: IV KUMULATIVNI NETO PRIMITCI (+5% TROŠKOVI) | C25: =C24 -> -3186802.2 | D25: =C25+D24 -> -3225434.8 | E25: =D25+E24 -> -3287711.6 | F25: =E25+F24 -> -3187525.1 | G25: =F25+G24 -> -2922692.2 | H25: =G25+H24 -> -2379532.7 | I25: =H25+I24 -> -1854668 | J25: =I25+J24 -> -1338045.8 | K25: =J25+K24 -> -821629.72 | ... M25: =L25+M24 -> 678416.88
B28: IZRAČUN DISKONTIRANOG RAZDOBLJA POVRATA ULOŽENIH SREDSTAVA - ANALIZA OSJETLJIVOSTI
B30: GODINA | C30: 2024 | D30: 2025 | E30: 2026 | F30: 2027 | G30: 2028 | H30: 2029 | I30: 2030 | J30: 2031 | K30: 2032 | L30: 2033 | M30: 2034 | N30: 2035 | O30: 2036
C31: 0 | D31: 1 | E31: 2 | F31: 3 | G31: 4 | H31: 5 | I31: 6 | J31: 7 | K31: 8 | L31: 9 | M31: 10 | N31: 11 | O31: 12
B32: DNT (-5 % PRIHODI) | C32: =C21*1/(1+$C$38)^C31 -> -3186802.2 | D32: =D21*1/(1+$C$38)^D31 -> -54086.994 | E32: =E21*1/(1+$C$38)^E31 -> -74097.973 | F32: =F21*1/(1+$C$38)^F31 -> 64039.23 | G32: =G21*1/(1+$C$38)^G31 -> 194469.65 | H32: =H21*1/(1+$C$38)^H31 -> 400290.47 | I32: =I21*1/(1+$C$38)^I31 -> 370288.96 | J32: =J21*1/(1+$C$38)^J31 -> 350534.93 | ... M32: =M21*1/(1+$C$38)^M31 -> 637209.87 | N32: =M32 -> 637209.87 | O32: =N32 -> 637209.87
B33: KUMULATIV DNT (-5% PRIHODI) | C33: =C32 -> -3186802.2 | D33: =C33+D32 -> -3240889.2 | E33: =D33+E32 -> -3314987.2 | F33: =E33+F32 -> -3250947.9 | G33: =F33+G32 -> -3056478.3 | H33: =G33+H32 -> -2656187.8 | I33: =H33+I32 -> -2285898.9 | J33: =I33+J32 -> -1935363.9 | K33: =J33+K32 -> -1597652.5 | ... O33: =N33+O32 -> 639328.46
B35: DNT (+5% TROŠKOVI) | C35: =C24*1/(1+$C$38)^C31 -> -3186802.2 | D35: =D24*1/(1+$C$38)^D31 -> -37236.226 | E35: =E24*1/(1+$C$38)^E31 -> -57856.268 | F35: =F24*1/(1+$C$38)^F31 -> 89710.909 | G35: =G24*1/(1+$C$38)^G31 -> 228570.12 | H35: =H24*1/(1+$C$38)^H31 -> 451842.25 | I35: =I24*1/(1+$C$38)^I31 -> 420841.71 | J35: =J24*1/(1+$C$38)^J31 -> 399260.48 | ... M35: =M24*1/(1+$C$38)^M31 -> 680840.58 | N35: =M35 -> 680840.58 | O35: =N35 -> 680840.58
B36: KOMULATIV DNT (+5% TROŠKOVI) | C36: =C35 -> -3186802.2 | D36: =C36+D35 -> -3224038.4 | E36: =D36+E35 -> -3281894.7 | F36: =E36+F35 -> -3192183.8 | G36: =F36+G35 -> -2963613.7 | H36: =G36+H35 -> -2511771.4 | I36: =H36+I35 -> -2090929.7 | J36: =I36+J35 -> -1691669.2 | K36: =J36+K35 -> -1306993.4 | ... O36: =N36+O35 -> 1106146.6
B38: Diskontna stopa | C38: =Kredit!C4 -> 0.0375

Sheet Analiza projekta
B2: STATIČKA OCJENA ZA 2030. GODINU
B4: POKAZATELJI EKONOMIČNOSTI
B6: Ekonomičnost ukupnog poslovanja | C6: ="=" -> = | D6: Ukupni prihodi | E6: ="=" -> = | F6: =RDG!H5 -> 2712960 | G6: ="=" -> = | H6: =F6/F7 -> 1.2794698
D7: Ukupni rashodi | F7: =RDG!H15 -> 2120378.3
B9: POKAZATELJI PROFITABILNOSTI
B11: Neto profitna marža | C11: ="=" -> = | D11: Neto dobit | E11: ="=" -> = | F11: =RDG!H18 -> 533323.56 | G11: ="=" -> = | H11: =F11/F12 -> 0.19658364
D12: Ukupni prihodi | F12: =RDG!H5 -> 2712960
B14: POKAZATELJI VEZANI UZ INVESTICIJU
B16: Rentabilnost ukupno uloženih sredstava | C16: ="=" -> = | D16: Neto dobit | E16: ="=" -> = | F16: =RDG!H18 -> 533323.56 | G16: ="=" -> = | H16: =F16/F17 -> 0.16735383
D17: Visina investicije | F17: ='In + Am'!D12 -> 3186802.2
B19: Obrtaj ukupno uloženih sredstava | C19: ="=" -> = | D19: Ukupni prihodi | E19: ="=" -> = | F19: =RDG!H5 -> 2712960 | G19: ="=" -> = | H19: =F19/F20 -> 0.85131107
D20: Visina investicije | F20: ='In + Am'!D12 -> 3186802.2
B22: Reprodukcijska sposobnost | C22: ="=" -> = | D22: Neto dobit + amortizacija | E22: ="=" -> = | F22: =RDG!H18+RDG!H13 -> 580174.77 | G22: ="=" -> = | H22: =F22/F23 -> 0.18205547
D23: Visina investicije | F23: ='In + Am'!D12 -> 3186802.2
B25: POKAZATELJI VEZANI UZ RAD
B27: Investicijsko opterećenje po zaposlenom | C27: ="=" -> = | D27: Visina investicije | E27: ="=" -> = | F27: ='In + Am'!D12 -> 3186802.2 | G27: ="=" -> = | H27: =F27/F28 -> 138556.62
D28: Broj zaposlenih | F28: =SUM(Plaće!H20:H21) -> 23
B32: DINAMIČKA OCJENA
B34: VRIJEME POVRATA (VP)
B36: VP | C36: ="=" -> = | D36: ='EK + FK'!K5+(ABS('EK + FK'!K18)/'EK + FK'!L17) -> 8.6093825
B39: DISKONTIRANO VRIJEME POVRATA (DVP)
B41: DVP | C41: ="=" -> = | D41: ='EK + FK'!L24+(ABS('EK + FK'!L26)/'EK + FK'!M25) -> 9.6802994
B44: NETO SADAŠNJA VRIJEDNOSTI (NSV) | F44: PROVJERA NETO SADAŠNJE VRIJEDNOSTI (NSV)
B46: NSV | C46: ="=" -> = | D46: {=NPV('EK + FK'!C28,'EK + FK'!D17:M17)-ABS('EK + FK'!C17)} -> 233727.02 | F46: NSV | G46: ="=" -> = | H46: =SUM('EK + FK'!D25:M25)+'EK + FK'!C25 -> 233727.02
B49: INTERNA STOPA RENTABILNOSTI (ISR)
B51: ISR | C51: ="=" -> = | D51: =IRR('EK + FK'!C17:M17) -> 0.047772028 | F51: PROVJERA INTERNE STOPE RENTABILNOSTI
F53: GODINA | G53: 2024 | H53: 2025 | I53: 2026 | J53: 2027 | K53: 2028 | L53: 2029 | M53: 2030 | N53: 2031 | O53: 2032 | P53: 2033 | Q53: 2034
B54: INDEKS PROFITABILNOSTI (IP) | G54: 0 | H54: 1 | I54: 2 | J54: 3 | K54: 4 | L54: 5 | M54: 6 | N54: 7 | O54: 8 | P54: 9 | Q54: 10
F55: DNT | G55: ='EK + FK'!C17*1/(1+$G$58)^G54 -> -3186802.2 | H55: ='EK + FK'!D17*1/(1+$G$58)^H54 -> 4990.3448 | I55: ='EK + FK'!E17*1/(1+$G$58)^I54 -> -16774.532 | J55: ='EK + FK'!F17*1/(1+$G$58)^J54 -> 128423.57 | K55: ='EK + FK'!G17*1/(1+$G$58)^K54 -> 262227.4 | L55: ='EK + FK'!H17*1/(1+$G$58)^L54 -> 476495.01 | M55: ='EK + FK'!I17*1/(1+$G$58)^M54 -> 451555.64 | N55: ='EK + FK'!J17*1/(1+$G$58)^N54 -> 425021.86 | ... Q55: ='EK + FK'!M17*1/(1+$G$58)^Q54 -> 662488.87
B56: IP | C56: ="=" -> = | D56: =SUM('EK + FK'!D25:M25)/ABS('EK + FK'!C25) -> 1.0733422 | F56: KOMULATIV DNT | G56: =G55 -> -3186802.2 | H56: =G56+H55 -> -3181811.9 | I56: =H56+I55 -> -3198586.4 | J56: =I56+J55 -> -3070162.8 | K56: =J56+K55 -> -2807935.4 | L56: =K56+L55 -> -2331440.4 | M56: =L56+M55 -> -1879884.8 | N56: =M56+N55 -> -1454862.9 | O56: =N56+O55 -> -1049361.4 | ... Q56: =P56+Q55 -> 0
F58: ISR | G58: ='Analiza projekta'!D51 -> 0.047772028
B61: ANALIZA OSJETLJIVOSTI
B63: Stavka | C63: Scenarij promjena
C64: Smanjenje prihoda za 5% | D64: Osnovna situacija | E64: Porast troškova za 5%
